Workbook

Sheet ADMIN_CONTROL
A1: @dropdown
B2: 🎛️ مركز التحكم الرئيسي - MASTER ADMIN CONTROL CENTER
B5: ⚙️ SYSTEM SETTINGS | F5: 📊 DATA MANAGEMENT | J5: 🎨 DISPLAY OPTIONS | N5: 🔧 QUICK ACTIONS
B7: Auto-Save: | C7: ON | F7: FAMILY NAMES LIST: | N7: =HYPERLINK("#QUICK_ADD!A1","➕ ADD PERSON") -> ➕ ADD PERSON
B8: Auto-Calculate: | C8: ON | F8: ال شايع | N8: =HYPERLINK("#REGISTRY!A1","🔍 SEARCH") -> 🔍 SEARCH
B9: Auto-Backup: | C9: DAILY | N9: =HYPERLINK("#DASHBOARD!A1","📊 DASHBOARD") -> 📊 DASHBOARD
B10: Language: | C10: AR/EN | N10: =HYPERLINK("#TREE!A1","🌳 TREE VIEW") -> 🌳 TREE VIEW
B11: Date Format: | C11: DD/MM/YYYY | N11: 💾 SAVE ALL
B14: 📈 LIVE STATISTICS
B15: Total Members: | C15: =COUNTA(REGISTRY!B:B)-1 -> 389
B16: Males: | C16: =COUNTIF(REGISTRY!G:G,"Male") -> 299
B17: Females: | C17: =COUNTIF(REGISTRY!G:G,"Female") -> 89
B18: Generations: | C18: =MAX(REGISTRY!K:K) -> 10
B19: Completion: | C19: =AVERAGE(REGISTRY!AG:AG) -> #DIV/0!

Sheet QUICK_ADD
B2: ⚡ إدخال سريع - QUICK SMART ENTRY
B5: 📝 Just enter the name and select father!
B7: الاسم فقط Name Only: | C7: ابراهيم | G7: 💡 How it works:
G8: 1️⃣ Type ONLY the first name
B9: اختر الأب Select Father: | C9: حمد | G9: 2️⃣ Select father from dropdown
G10: 3️⃣ Everything else fills automatically!
B11: الجنس Gender: | C11: Male | G11: 4️⃣ Click ADD button
B12: سنة الميلاد Birth Year: | C12: =2025-25 -> 2000 | G12: ✅ Person added with all relationships!
B14: 🔄 AUTO-FILLED DATA
B15: Father's Name: | C15: حمد
B16: Grandfather: | C16: =IF(C9<>"",VLOOKUP(C9,REGISTRY!A:C,3,FALSE),"") -> #N/A
B17: Family Name: | C17: =IF(C9<>"",VLOOKUP(C9,REGISTRY!A:E,5,FALSE),"") -> #N/A
B18: Generation: | C18: =IF(C9<>"",VLOOKUP(C9,REGISTRY!A:K,11,FALSE)+1,1) -> #N/A
B19: New ID: | C19: ="P"&TEXT(COUNTA(REGISTRY!B:B),"000") -> P390
C21: ➕ ADD TO REGISTRY

Sheet DASHBOARD
A1: 📊 لوحة المعلومات المتقدمة - ADVANCED ANALYTICS DASHBOARD
B4: 👥 TOTAL الإجمالي | E4: 👨 MALES الذكور | H4: 👩 FEMALES الإناث | K4: 🌳 GENERATIONS الأجيال
B7: =COUNTA(REGISTRY!B:B)-1 -> 389 | E7: =COUNTIF(REGISTRY!G:G,"Male") -> 299 | H7: =COUNTIF(REGISTRY!G:G,"Female") -> 89 | K7: =MAX(REGISTRY!K:K) -> 10
B9: 📈 GENERATION ANALYSIS | H9: 🌿 BRANCH ANALYSIS
B10: Generation | C10: Count | D10: Males | E10: Females | F10: Avg Children | H10: Branch | I10: Members | J10: Percentage
B11: Generation 1 | C11: =COUNTIF(REGISTRY!K:K,1) -> 594 | D11: =COUNTIFS(REGISTRY!K:K,1,REGISTRY!G:G,"Male") -> 0 | E11: =COUNTIFS(REGISTRY!K:K,1,REGISTRY!G:G,"Female") -> 0 | F11: =IFERROR(AVERAGEIF(REGISTRY!K:K,1,REGISTRY!P:P),0) -> 0.0050505051 | H11: الأصل | I11: =COUNTIF(REGISTRY!L:L,"الأصل") -> 594 | J11: =IFERROR(I11/(COUNTA(REGISTRY!B:B)-1)*100,0) -> 152.69923
B12: Generation 2 | C12: =COUNTIF(REGISTRY!K:K,2) -> 3 | D12: =COUNTIFS(REGISTRY!K:K,2,REGISTRY!G:G,"Male") -> 3 | E12: =COUNTIFS(REGISTRY!K:K,2,REGISTRY!G:G,"Female") -> 0 | F12: =IFERROR(AVERAGEIF(REGISTRY!K:K,2,REGISTRY!P:P),0) -> 0 | H12: الفرع 1 | I12: =COUNTIF(REGISTRY!L:L,"الفرع 1") -> 0 | J12: =IFERROR(I12/(COUNTA(REGISTRY!B:B)-1)*100,0) -> 0
B13: Generation 3 | C13: =COUNTIF(REGISTRY!K:K,3) -> 7 | D13: =COUNTIFS(REGISTRY!K:K,3,REGISTRY!G:G,"Male") -> 7 | E13: =COUNTIFS(REGISTRY!K:K,3,REGISTRY!G:G,"Female") -> 0 | F13: =IFERROR(AVERAGEIF(REGISTRY!K:K,3,REGISTRY!P:P),0) -> 0 | H13: الفرع 2 | I13: =COUNTIF(REGISTRY!L:L,"الفرع 2") -> 0 | J13: =IFERROR(I13/(COUNTA(REGISTRY!B:B)-1)*100,0) -> 0
B14: Generation 4 | C14: =COUNTIF(REGISTRY!K:K,4) -> 15 | D14: =COUNTIFS(REGISTRY!K:K,4,REGISTRY!G:G,"Male") -> 15 | E14: =COUNTIFS(REGISTRY!K:K,4,REGISTRY!G:G,"Female") -> 0 | F14: =IFERROR(AVERAGEIF(REGISTRY!K:K,4,REGISTRY!P:P),0) -> 0 | H14: الفرع 3 | I14: =COUNTIF(REGISTRY!L:L,"الفرع 3") -> 0 | J14: =IFERROR(I14/(COUNTA(REGISTRY!B:B)-1)*100,0) -> 0
B15: Generation 5 | C15: =COUNTIF(REGISTRY!K:K,5) -> 24 | D15: =COUNTIFS(REGISTRY!K:K,5,REGISTRY!G:G,"Male") -> 24 | E15: =COUNTIFS(REGISTRY!K:K,5,REGISTRY!G:G,"Female") -> 0 | F15: =IFERROR(AVERAGEIF(REGISTRY!K:K,5,REGISTRY!P:P),0) -> 0 | H15: الفرع 4 | I15: =COUNTIF(REGISTRY!L:L,"الفرع 4") -> 0 | J15: =IFERROR(I15/(COUNTA(REGISTRY!B:B)-1)*100,0) -> 0
B16: Generation 6 | C16: =COUNTIF(REGISTRY!K:K,6) -> 101 | D16: =COUNTIFS(REGISTRY!K:K,6,REGISTRY!G:G,"Male") -> 79 | E16: =COUNTIFS(REGISTRY!K:K,6,REGISTRY!G:G,"Female") -> 22 | F16: =IFERROR(AVERAGEIF(REGISTRY!K:K,6,REGISTRY!P:P),0) -> 0
B17: Generation 7 | C17: =COUNTIF(REGISTRY!K:K,7) -> 190 | D17: =COUNTIFS(REGISTRY!K:K,7,REGISTRY!G:G,"Male") -> 135 | E17: =COUNTIFS(REGISTRY!K:K,7,REGISTRY!G:G,"Female") -> 55 | F17: =IFERROR(AVERAGEIF(REGISTRY!K:K,7,REGISTRY!P:P),0) -> 0
B18: Generation 8 | C18: =COUNTIF(REGISTRY!K:K,8) -> 43 | D18: =COUNTIFS(REGISTRY!K:K,8,REGISTRY!G:G,"Male") -> 31 | E18: =COUNTIFS(REGISTRY!K:K,8,REGISTRY!G:G,"Female") -> 12
B20: 📊 FAMILY GROWTH TREND | H20: ✅ DATA COMPLETION
H21: =AVERAGE(REGISTRY!AG:AG)&"%" -> #DIV/0!

Sheet REGISTRY
A1: ID | B1: Name الاسم | C1: Father الأب | D1: Grandfather الجد | E1: الجد الثاني | F1: Father_ID | G1: Gender | H1: Birth_Year | I1: Sons | J1: Daughters | K1: Generation | L1: Branch | M1: Full_Name_AR | N1: Full_Name_EN | O1: Age | P1: Children | Q1: Phone | R1: City | S1: Status
A2: ="P"&TEXT(ROW()-1,"000") -> P001 | B2: حمد | E2: ال شايع | H2: 1600 | I2: 3 | K2: =IF(F2="",1,IFERROR(VLOOKUP(F2,A:K,11,FALSE)+1,1)) -> 1 | L2: =IF(F2="","الأصل",IF(VLOOKUP(F2,A:L,12,FALSE)="الأصل","الفرع "&K2-1,VLOOKUP(F2,A:L,12,FALSE))) -> الأصل | M2: =IF(B2<>"",IF(C2<>"",CONCATENATE(B2," بن ",C2," بن ",D2," ",E2),CONCATENATE(B2," ",E2)),"") -> حمد ال شايع | N2: =IF(B2<>"",IF(C2<>"",CONCATENATE(B2," bin ",C2," bin ",D2," Al-",E2),CONCATENATE(B2," Al-",E2)),"") -> حمد Al-ال شايع | O2: =IF(H2<>"",YEAR(TODAY())-H2,"") -> 425 | P2: =I2+J2 -> 3 | S2: =IF(B2<>"","Living","") -> Living
A3: ="P"&TEXT(ROW()-1,"000") -> P002 | B3: ابراهيم | C3: حمد | D3: - | F3: P001 | G3: Male | K3: =IF(F3="",1,IFERROR(VLOOKUP(F3,A:K,11,FALSE)+1,1)) -> 2 | L3: الابراهيم | M3: =IF(B3<>"",IF(C3<>"",CONCATENATE(B3," بن ",C3," بن ",D3," ",E3),CONCATENATE(B3," ",E3)),"") -> ابراهيم بن حمد بن - | N3: =IF(B3<>"",IF(C3<>"",CONCATENATE(B3," bin ",C3," bin ",D3," Al-",E3),CONCATENATE(B3," Al-",E3)),"") -> ابراهيم bin حمد bin - Al- | O3: =IF(H3<>"",YEAR(TODAY())-H3,"") | P3: =I3+J3 -> 0 | S3: =IF(B3<>"","Living","") -> Living
A4: ="P"&TEXT(ROW()-1,"000") -> P003 | B4: عبدالكريم | C4: حمد | D4: - | F4: P001 | G4: Male | K4: =IF(F4="",1,IFERROR(VLOOKUP(F4,A:K,11,FALSE)+1,1)) -> 2 | L4: العبدالكريم | M4: =IF(B4<>"",IF(C4<>"",CONCATENATE(B4," بن ",C4," بن ",D4," ",E4),CONCATENATE(B4," ",E4)),"") -> عبدالكريم بن حمد بن - | N4: =IF(B4<>"",IF(C4<>"",CONCATENATE(B4," bin ",C4," bin ",D4," Al-",E4),CONCATENATE(B4," Al-",E4)),"") -> عبدالكريم bin حمد bin - Al- | O4: =IF(H4<>"",YEAR(TODAY())-H4,"") | P4: =I4+J4 -> 0 | S4: =IF(B4<>"","Living","") -> Living
A5: ="P"&TEXT(ROW()-1,"000") -> P004 | B5: فوزان | C5: حمد | D5: - | F5: P001 | G5: Male | K5: =IF(F5="",1,IFERROR(VLOOKUP(F5,A:K,11,FALSE)+1,1)) -> 2 | L5: الفوزان | M5: =IF(B5<>"",IF(C5<>"",CONCATENATE(B5," بن ",C5," بن ",D5," ",E5),CONCATENATE(B5," ",E5)),"") -> فوزان بن حمد بن - | N5: =IF(B5<>"",IF(C5<>"",CONCATENATE(B5," bin ",C5," bin ",D5," Al-",E5),CONCATENATE(B5," Al-",E5)),"") -> فوزان bin حمد bin - Al- | O5: =IF(H5<>"",YEAR(TODAY())-H5,"") | P5: =I5+J5 -> 0 | S5: =IF(B5<>"","Living","") -> Living
A6: ="P"&TEXT(ROW()-1,"000") -> P005 | B6: محمد | C6: ابراهيم | D6: حمد | F6: P002 | G6: Male | K6: =IF(F6="",1,IFERROR(VLOOKUP(F6,A:K,11,FALSE)+1,1)) -> 3 | L6: =IF(F6="","الأصل",IF(VLOOKUP(F6,A:L,12,FALSE)="الأصل","الفرع "&K6-1,VLOOKUP(F6,A:L,12,FALSE))) -> الابراهيم | M6: =IF(B6<>"",IF(C6<>"",CONCATENATE(B6," بن ",C6," بن ",D6," ",E6),CONCATENATE(B6," ",E6)),"") -> محمد بن ابراهيم بن حمد | N6: =IF(B6<>"",IF(C6<>"",CONCATENATE(B6," bin ",C6," bin ",D6," Al-",E6),CONCATENATE(B6," Al-",E6)),"") -> محمد bin ابراهيم bin حمد Al- | O6: =IF(H6<>"",YEAR(TODAY())-H6,"") | P6: =I6+J6 -> 0 | S6: =IF(B6<>"","Living","") -> Living
A7: ="P"&TEXT(ROW()-1,"000") -> P006 | B7: ناصر | C7: ابراهيم | D7: حمد | F7: P002 | G7: Male | K7: =IF(F7="",1,IFERROR(VLOOKUP(F7,A:K,11,FALSE)+1,1)) -> 3 | L7: =IF(F7="","الأصل",IF(VLOOKUP(F7,A:L,12,FALSE)="الأصل","الفرع "&K7-1,VLOOKUP(F7,A:L,12,FALSE))) -> الابراهيم | M7: =IF(B7<>"",IF(C7<>"",CONCATENATE(B7," بن ",C7," بن ",D7," ",E7),CONCATENATE(B7," ",E7)),"") -> ناصر بن ابراهيم بن حمد | N7: =IF(B7<>"",IF(C7<>"",CONCATENATE(B7," bin ",C7," bin ",D7," Al-",E7),CONCATENATE(B7," Al-",E7)),"") -> ناصر bin ابراهيم bin حمد Al- | O7: =IF(H7<>"",YEAR(TODAY())-H7,"") | P7: =I7+J7 -> 0 | S7: =IF(B7<>"","Living","") -> Living
A8: ="P"&TEXT(ROW()-1,"000") -> P007 | B8: ابراهيم | C8: محمد | D8: ابراهيم | E8: حمد | F8: P005 | G8: Male | K8: =IF(F8="",1,IFERROR(VLOOKUP(F8,A:K,11,FALSE)+1,1)) -> 4 | L8: =IF(F8="","الأصل",IF(VLOOKUP(F8,A:L,12,FALSE)="الأصل","الفرع "&K8-1,VLOOKUP(F8,A:L,12,FALSE))) -> الابراهيم | M8: =IF(B8<>"",IF(C8<>"",CONCATENATE(B8," بن ",C8," بن ",D8," ",E8),CONCATENATE(B8," ",E8)),"") -> ابراهيم بن محمد بن ابراهيم حمد | N8: =IF(B8<>"",IF(C8<>"",CONCATENATE(B8," bin ",C8," bin ",D8," Al-",E8),CONCATENATE(B8," Al-",E8)),"") -> ابراهيم bin محمد bin ابراهيم Al-حمد | O8: =IF(H8<>"",YEAR(TODAY())-H8,"") | P8: =I8+J8 -> 0 | S8: =IF(B8<>"","Living","") -> Living
A9: ="P"&TEXT(ROW()-1,"000") -> P008 | B9: عبدالمحسن | C9: محمد | D9: ابراهيم | E9: حمد | F9: P005 | G9: Male | K9: =IF(F9="",1,IFERROR(VLOOKUP(F9,A:K,11,FALSE)+1,1)) -> 4 | L9: =IF(F9="","الأصل",IF(VLOOKUP(F9,A:L,12,FALSE)="الأصل","الفرع "&K9-1,VLOOKUP(F9,A:L,12,FALSE))) -> الابراهيم | M9: =IF(B9<>"",IF(C9<>"",CONCATENATE(B9," بن ",C9," بن ",D9," ",E9),CONCATENATE(B9," ",E9)),"") -> عبدالمحسن بن محمد بن ابراهيم حمد | N9: =IF(B9<>"",IF(C9<>"",CONCATENATE(B9," bin ",C9," bin ",D9," Al-",E9),CONCATENATE(B9," Al-",E9)),"") -> عبدالمحسن bin محمد bin ابراهيم Al-حمد | O9: =IF(H9<>"",YEAR(TODAY())-H9,"") | P9: =I9+J9 -> 0 | S9: =IF(B9<>"","Living","") -> Living
A10: ="P"&TEXT(ROW()-1,"000") -> P009 | B10: عبدالرحمن | C10: محمد | D10: ابراهيم | E10: حمد | F10: P005 | G10: Male | K10: =IF(F10="",1,IFERROR(VLOOKUP(F10,A:K,11,FALSE)+1,1)) -> 4 | L10: =IF(F10="","الأصل",IF(VLOOKUP(F10,A:L,12,FALSE)="الأصل","الفرع "&K10-1,VLOOKUP(F10,A:L,12,FALSE))) -> الابراهيم | M10: =IF(B10<>"",IF(C10<>"",CONCATENATE(B10," بن ",C10," بن ",D10," ",E10),CONCATENATE(B10," ",E10)),"") -> عبدالرحمن بن محمد بن ابراهيم حمد | N10: =IF(B10<>"",IF(C10<>"",CONCATENATE(B10," bin ",C10," bin ",D10," Al-",E10),CONCATENATE(B10," Al-",E10)),"") -> عبدالرحمن bin محمد bin ابراهيم Al-حمد | O10: =IF(H10<>"",YEAR(TODAY())-H10,"") | P10: =I10+J10 -> 0 | S10: =IF(B10<>"","Living","") -> Living
A11: ="P"&TEXT(ROW()-1,"000") -> P010 | B11: عبدالمحسن | C11: ناصر | D11: ابراهيم | E11: حمد | F11: P006 | G11: Male | K11: =IF(F11="",1,IFERROR(VLOOKUP(F11,A:K,11,FALSE)+1,1)) -> 4 | L11: =IF(F11="","الأصل",IF(VLOOKUP(F11,A:L,12,FALSE)="الأصل","الفرع "&K11-1,VLOOKUP(F11,A:L,12,FALSE))) -> الابراهيم | M11: =IF(B11<>"",IF(C11<>"",CONCATENATE(B11," بن ",C11," بن ",D11," ",E11),CONCATENATE(B11," ",E11)),"") -> عبدالمحسن بن ناصر بن ابراهيم حمد | N11: =IF(B11<>"",IF(C11<>"",CONCATENATE(B11," bin ",C11," bin ",D11," Al-",E11),CONCATENATE(B11," Al-",E11)),"") -> عبدالمحسن bin ناصر bin ابراهيم Al-حمد | O11: =IF(H11<>"",YEAR(TODAY())-H11,"") | P11: =I11+J11 -> 0 | S11: =IF(B11<>"","Living","") -> Living
A12: ="P"&TEXT(ROW()-1,"000") -> P011 | B12: ابراهيم | C12: ناصر | D12: ابراهيم | E12: حمد | F12: P006 | G12: Male | K12: =IF(F12="",1,IFERROR(VLOOKUP(F12,A:K,11,FALSE)+1,1)) -> 4 | L12: =IF(F12="","الأصل",IF(VLOOKUP(F12,A:L,12,FALSE)="الأصل","الفرع "&K12-1,VLOOKUP(F12,A:L,12,FALSE))) -> الابراهيم | M12: =IF(B12<>"",IF(C12<>"",CONCATENATE(B12," بن ",C12," بن ",D12," ",E12),CONCATENATE(B12," ",E12)),"") -> ابراهيم بن ناصر بن ابراهيم حمد | N12: =IF(B12<>"",IF(C12<>"",CONCATENATE(B12," bin ",C12," bin ",D12," Al-",E12),CONCATENATE(B12," Al-",E12)),"") -> ابراهيم bin ناصر bin ابراهيم Al-حمد | O12: =IF(H12<>"",YEAR(TODAY())-H12,"") | P12: =I12+J12 -> 0 | S12: =IF(B12<>"","Living","") -> Living
A13: ="P"&TEXT(ROW()-1,"000") -> P012 | B13: ناصر | C13: ابراهيم | D13: ناصر | E13: ابراهيم | F13: P011 | G13: Male | K13: =IF(F13="",1,IFERROR(VLOOKUP(F13,A:K,11,FALSE)+1,1)) -> 5 | L13: =IF(F13="","الأصل",IF(VLOOKUP(F13,A:L,12,FALSE)="الأصل","الفرع "&K13-1,VLOOKUP(F13,A:L,12,FALSE))) -> الابراهيم | M13: =IF(B13<>"",IF(C13<>"",CONCATENATE(B13," بن ",C13," بن ",D13," ",E13),CONCATENATE(B13," ",E13)),"") -> ناصر بن ابراهيم بن ناصر ابراهيم | N13: =IF(B13<>"",IF(C13<>"",CONCATENATE(B13," bin ",C13," bin ",D13," Al-",E13),CONCATENATE(B13," Al-",E13)),"") -> ناصر bin ابراهيم bin ناصر Al-ابراهيم | O13: =IF(H13<>"",YEAR(TODAY())-H13,"") | P13: =I13+J13 -> 0 | S13: =IF(B13<>"","Living","") -> Living
A14: ="P"&TEXT(ROW()-1,"000") -> P013 | B14: عبدالرحمن | C14: ابراهيم | D14: ناصر | E14: ابراهيم | F14: P011 | G14: Male | K14: =IF(F14="",1,IFERROR(VLOOKUP(F14,A:K,11,FALSE)+1,1)) -> 5 | L14: =IF(F14="","الأصل",IF(VLOOKUP(F14,A:L,12,FALSE)="الأصل","الفرع "&K14-1,VLOOKUP(F14,A:L,12,FALSE))) -> الابراهيم | M14: =IF(B14<>"",IF(C14<>"",CONCATENATE(B14," بن ",C14," بن ",D14," ",E14),CONCATENATE(B14," ",E14)),"") -> عبدالرحمن بن ابراهيم بن ناصر ابراهيم | N14: =IF(B14<>"",IF(C14<>"",CONCATENATE(B14," bin ",C14," bin ",D14," Al-",E14),CONCATENATE(B14," Al-",E14)),"") -> عبدالرحمن bin ابراهيم bin ناصر Al-ابراهيم | O14: =IF(H14<>"",YEAR(TODAY())-H14,"") | P14: =I14+J14 -> 0 | S14: =IF(B14<>"","Living","") -> Living
A15: ="P"&TEXT(ROW()-1,"000") -> P014 | B15: عبدالكريم | C15: ابراهيم | D15: ناصر | E15: ابراهيم | F15: P011 | G15: Male | K15: =IF(F15="",1,IFERROR(VLOOKUP(F15,A:K,11,FALSE)+1,1)) -> 5 | L15: =IF(F15="","الأصل",IF(VLOOKUP(F15,A:L,12,FALSE)="الأصل","الفرع "&K15-1,VLOOKUP(F15,A:L,12,FALSE))) -> الابراهيم | M15: =IF(B15<>"",IF(C15<>"",CONCATENATE(B15," بن ",C15," بن ",D15," ",E15),CONCATENATE(B15," ",E15)),"") -> عبدالكريم بن ابراهيم بن ناصر ابراهيم | N15: =IF(B15<>"",IF(C15<>"",CONCATENATE(B15," bin ",C15," bin ",D15," Al-",E15),CONCATENATE(B15," Al-",E15)),"") -> عبدالكريم bin ابراهيم bin ناصر Al-ابراهيم | O15: =IF(H15<>"",YEAR(TODAY())-H15,"") | P15: =I15+J15 -> 0 | S15: =IF(B15<>"","Living","") -> Living
A16: ="P"&TEXT(ROW()-1,"000") -> P015 | B16: عبدالعزيز | C16: ابراهيم | D16: ناصر | E16: ابراهيم | F16: P011 | G16: Male | K16: =IF(F16="",1,IFERROR(VLOOKUP(F16,A:K,11,FALSE)+1,1)) -> 5 | L16: =IF(F16="","الأصل",IF(VLOOKUP(F16,A:L,12,FALSE)="الأصل","الفرع "&K16-1,VLOOKUP(F16,A:L,12,FALSE))) -> الابراهيم | M16: =IF(B16<>"",IF(C16<>"",CONCATENATE(B16," بن ",C16," بن ",D16," ",E16),CONCATENATE(B16," ",E16)),"") -> عبدالعزيز بن ابراهيم بن ناصر ابراهيم | N16: =IF(B16<>"",IF(C16<>"",CONCATENATE(B16," bin ",C16," bin ",D16," Al-",E16),CONCATENATE(B16," Al-",E16)),"") -> عبدالعزيز bin ابراهيم bin ناصر Al-ابراهيم | O16: =IF(H16<>"",YEAR(TODAY())-H16,"") | P16: =I16+J16 -> 0 | S16: =IF(B16<>"","Living","") -> Living
A17: ="P"&TEXT(ROW()-1,"000") -> P016 | B17: محمد | C17: ناصر | D17: ابراهيم | E17: ناصر | F17: P012 | G17: Male | K17: =IF(F17="",1,IFERROR(VLOOKUP(F17,A:K,11,FALSE)+1,1)) -> 6 | L17: =IF(F17="","الأصل",IF(VLOOKUP(F17,A:L,12,FALSE)="الأصل","الفرع "&K17-1,VLOOKUP(F17,A:L,12,FALSE))) -> الابراهيم | M17: =IF(B17<>"",IF(C17<>"",CONCATENATE(B17," بن ",C17," بن ",D17," ",E17),CONCATENATE(B17," ",E17)),"") -> محمد بن ناصر بن ابراهيم ناصر | N17: =IF(B17<>"",IF(C17<>"",CONCATENATE(B17," bin ",C17," bin ",D17," Al-",E17),CONCATENATE(B17," Al-",E17)),"") -> محمد bin ناصر bin ابراهيم Al-ناصر | O17: =IF(H17<>"",YEAR(TODAY())-H17,"") | P17: =I17+J17 -> 0 | S17: =IF(B17<>"","Living","") -> Living
A18: ="P"&TEXT(ROW()-1,"000") -> P017 | B18: ابراهيم | C18: ناصر | D18: ابراهيم | E18: ناصر | F18: P012 | G18: Male | K18: =IF(F18="",1,IFERROR(VLOOKUP(F18,A:K,11,FALSE)+1,1)) -> 6 | L18: =IF(F18="","الأصل",IF(VLOOKUP(F18,A:L,12,FALSE)="الأصل","الفرع "&K18-1,VLOOKUP(F18,A:L,12,FALSE))) -> الابراهيم | M18: =IF(B18<>"",IF(C18<>"",CONCATENATE(B18," بن ",C18," بن ",D18," ",E18),CONCATENATE(B18," ",E18)),"") -> ابراهيم بن ناصر بن ابراهيم ناصر | N18: =IF(B18<>"",IF(C18<>"",CONCATENATE(B18," bin ",C18," bin ",D18," Al-",E18),CONCATENATE(B18," Al-",E18)),"") -> ابراهيم bin ناصر bin ابراهيم Al-ناصر | O18: =IF(H18<>"",YEAR(TODAY())-H18,"") | P18: =I18+J18 -> 0 | S18: =IF(B18<>"","Living","") -> Living
A19: ="P"&TEXT(ROW()-1,"000") -> P018 | B19: سعد | C19: ناصر | D19: ابراهيم | E19: ناصر | F19: P012 | G19: Male | K19: =IF(F19="",1,IFERROR(VLOOKUP(F19,A:K,11,FALSE)+1,1)) -> 6 | L19: =IF(F19="","الأصل",IF(VLOOKUP(F19,A:L,12,FALSE)="الأصل","الفرع "&K19-1,VLOOKUP(F19,A:L,12,FALSE))) -> الابراهيم | M19: =IF(B19<>"",IF(C19<>"",CONCATENATE(B19," بن ",C19," بن ",D19," ",E19),CONCATENATE(B19," ",E19)),"") -> سعد بن ناصر بن ابراهيم ناصر | N19: =IF(B19<>"",IF(C19<>"",CONCATENATE(B19," bin ",C19," bin ",D19," Al-",E19),CONCATENATE(B19," Al-",E19)),"") -> سعد bin ناصر bin ابراهيم Al-ناصر | O19: =IF(H19<>"",YEAR(TODAY())-H19,"") | P19: =I19+J19 -> 0 | S19: =IF(B19<>"","Living","") -> Living
... A234: ="P"&TEXT(ROW()-1,"000") -> P233 | B234: عبدالله | C234: عبدالرحمن | D234: محمد | E234: فوزان | F234: P228 | G234: Male | K234: =IF(F234="",1,IFERROR(VLOOKUP(F234,A:K,11,FALSE)+1,1)) -> 9 | L234: =IF(F234="","الأصل",IF(VLOOKUP(F234,A:L,12,FALSE)="الأصل","الفرع "&K234-1,VLOOKUP(F234,A:L,12,FALSE))) -> الفوزان | M234: =IF(B234<>"",IF(C234<>"",CONCATENATE(B234," بن ",C234," بن ",D234," ",E234),CONCATENATE(B234," ",E234)),"") -> عبدالله بن عبدالرحمن بن محمد فوزان | N234: =IF(B234<>"",IF(C234<>"",CONCATENATE(B234," bin ",C234," bin ",D234," Al-",E234),CONCATENATE(B234," Al-",E234)),"") -> عبدالله bin عبدالرحمن bin محمد Al-فوزان | O234: =IF(H234<>"",YEAR(TODAY())-H234,"") | P234: =I234+J234 -> 0 | S234: =IF(B234<>"","Living","") -> Living
A235: ="P"&TEXT(ROW()-1,"000") -> P234 | B235: عبدالله | C235: عبدالكريم | D235: حمد | F235: P003 | G235: Male | K235: =IF(F235="",1,IFERROR(VLOOKUP(F235,A:K,11,FALSE)+1,1)) -> 3 | L235: =IF(F235="","الأصل",IF(VLOOKUP(F235,A:L,12,FALSE)="الأصل","الفرع "&K235-1,VLOOKUP(F235,A:L,12,FALSE))) -> العبدالكريم | M235: =IF(B235<>"",IF(C235<>"",CONCATENATE(B235," بن ",C235," بن ",D235," ",E235),CONCATENATE(B235," ",E235)),"") -> عبدالله بن عبدالكريم بن حمد | N235: =IF(B235<>"",IF(C235<>"",CONCATENATE(B235," bin ",C235," bin ",D235," Al-",E235),CONCATENATE(B235," Al-",E235)),"") -> عبدالله bin عبدالكريم bin حمد Al- | O235: =IF(H235<>"",YEAR(TODAY())-H235,"") | P235: =I235+J235 -> 0 | S235: =IF(B235<>"","Living","") -> Living
A236: ="P"&TEXT(ROW()-1,"000") -> P235 | B236: عبدالكريم | C236: عبدالله | D236: عبدالكريم | E236: حمد | F236: P234 | G236: Male | K236: =IF(F236="",1,IFERROR(VLOOKUP(F236,A:K,11,FALSE)+1,1)) -> 4 | L236: =IF(F236="","الأصل",IF(VLOOKUP(F236,A:L,12,FALSE)="الأصل","الفرع "&K236-1,VLOOKUP(F236,A:L,12,FALSE))) -> العبدالكريم | M236: =IF(B236<>"",IF(C236<>"",CONCATENATE(B236," بن ",C236," بن ",D236," ",E236),CONCATENATE(B236," ",E236)),"") -> عبدالكريم بن عبدالله بن عبدالكريم حمد | N236: =IF(B236<>"",IF(C236<>"",CONCATENATE(B236," bin ",C236," bin ",D236," Al-",E236),CONCATENATE(B236," Al-",E236)),"") -> عبدالكريم bin عبدالله bin عبدالكريم Al-حمد | O236: =IF(H236<>"",YEAR(TODAY())-H236,"") | P236: =I236+J236 -> 0 | S236: =IF(B236<>"","Living","") -> Living
A237: ="P"&TEXT(ROW()-1,"000") -> P236 | B237: محمد | C237: عبدالله | D237: عبدالكريم | E237: حمد | F237: P234 | G237: Male | K237: =IF(F237="",1,IFERROR(VLOOKUP(F237,A:K,11,FALSE)+1,1)) -> 4 | L237: =IF(F237="","الأصل",IF(VLOOKUP(F237,A:L,12,FALSE)="الأصل","الفرع "&K237-1,VLOOKUP(F237,A:L,12,FALSE))) -> العبدالكريم | M237: =IF(B237<>"",IF(C237<>"",CONCATENATE(B237," بن ",C237," بن ",D237," ",E237),CONCATENATE(B237," ",E237)),"") -> محمد بن عبدالله بن عبدالكريم حمد | N237: =IF(B237<>"",IF(C237<>"",CONCATENATE(B237," bin ",C237," bin ",D237," Al-",E237),CONCATENATE(B237," Al-",E237)),"") -> محمد bin عبدالله bin عبدالكريم Al-حمد | O237: =IF(H237<>"",YEAR(TODAY())-H237,"") | P237: =I237+J237 -> 0 | S237: =IF(B237<>"","Living","") -> Living
A238: ="P"&TEXT(ROW()-1,"000") -> P237 | B238: عثمان | C238: محمد | D238: عبدالله | E238: عبدالكريم | F238: P236 | G238: Male | K238: =IF(F238="",1,IFERROR(VLOOKUP(F238,A:K,11,FALSE)+1,1)) -> 5 | L238: =IF(F238="","الأصل",IF(VLOOKUP(F238,A:L,12,FALSE)="الأصل","الفرع "&K238-1,VLOOKUP(F238,A:L,12,FALSE))) -> العبدالكريم | M238: =IF(B238<>"",IF(C238<>"",CONCATENATE(B238," بن ",C238," بن ",D238," ",E238),CONCATENATE(B238," ",E238)),"") -> عثمان بن محمد بن عبدالله عبدالكريم | N238: =IF(B238<>"",IF(C238<>"",CONCATENATE(B238," bin ",C238," bin ",D238," Al-",E238),CONCATENATE(B238," Al-",E238)),"") -> عثمان bin محمد bin عبدالله Al-عبدالكريم | O238: =IF(H238<>"",YEAR(TODAY())-H238,"") | P238: =I238+J238 -> 0 | S238: =IF(B238<>"","Living","") -> Living
A239: ="P"&TEXT(ROW()-1,"000") -> P238 | B239: عبدالعزيز | C239: محمد | D239: عبدالله | E239: عبدالكريم | F239: P236 | G239: Male | K239: =IF(F239="",1,IFERROR(VLOOKUP(F239,A:K,11,FALSE)+1,1)) -> 5 | L239: =IF(F239="","الأصل",IF(VLOOKUP(F239,A:L,12,FALSE)="الأصل","الفرع "&K239-1,VLOOKUP(F239,A:L,12,FALSE))) -> العبدالكريم | M239: =IF(B239<>"",IF(C239<>"",CONCATENATE(B239," بن ",C239," بن ",D239," ",E239),CONCATENATE(B239," ",E239)),"") -> عبدالعزيز بن محمد بن عبدالله عبدالكريم | N239: =IF(B239<>"",IF(C239<>"",CONCATENATE(B239," bin ",C239," bin ",D239," Al-",E239),CONCATENATE(B239," Al-",E239)),"") -> عبدالعزيز bin محمد bin عبدالله Al-عبدالكريم | O239: =IF(H239<>"",YEAR(TODAY())-H239,"") | P239: =I239+J239 -> 0 | S239: =IF(B239<>"","Living","") -> Living
A240: ="P"&TEXT(ROW()-1,"000") -> P239 | B240: عبدالله | C240: محمد | D240: عبدالله | E240: عبدالكريم | F240: P236 | G240: Male | K240: =IF(F240="",1,IFERROR(VLOOKUP(F240,A:K,11,FALSE)+1,1)) -> 5 | L240: =IF(F240="","الأصل",IF(VLOOKUP(F240,A:L,12,FALSE)="الأصل","الفرع "&K240-1,VLOOKUP(F240,A:L,12,FALSE))) -> العبدالكريم | M240: =IF(B240<>"",IF(C240<>"",CONCATENATE(B240," بن ",C240," بن ",D240," ",E240),CONCATENATE(B240," ",E240)),"") -> عبدالله بن محمد بن عبدالله عبدالكريم | N240: =IF(B240<>"",IF(C240<>"",CONCATENATE(B240," bin ",C240," bin ",D240," Al-",E240),CONCATENATE(B240," Al-",E240)),"") -> عبدالله bin محمد bin عبدالله Al-عبدالكريم | O240: =IF(H240<>"",YEAR(TODAY())-H240,"") | P240: =I240+J240 -> 0 | S240: =IF(B240<>"","Living","") -> Living
A241: ="P"&TEXT(ROW()-1,"000") -> P240 | B241: محمد | C241: عبدالله | D241: محمد | E241: عبدالله | F241: P239 | G241: Male | K241: =IF(F241="",1,IFERROR(VLOOKUP(F241,A:K,11,FALSE)+1,1)) -> 6 | L241: =IF(F241="","الأصل",IF(VLOOKUP(F241,A:L,12,FALSE)="الأصل","الفرع "&K241-1,VLOOKUP(F241,A:L,12,FALSE))) -> العبدالكريم | M241: =IF(B241<>"",IF(C241<>"",CONCATENATE(B241," بن ",C241," بن ",D241," ",E241),CONCATENATE(B241," ",E241)),"") -> محمد بن عبدالله بن محمد عبدالله | N241: =IF(B241<>"",IF(C241<>"",CONCATENATE(B241," bin ",C241," bin ",D241," Al-",E241),CONCATENATE(B241," Al-",E241)),"") -> محمد bin عبدالله bin محمد Al-عبدالله | O241: =IF(H241<>"",YEAR(TODAY())-H241,"") | P241: =I241+J241 -> 0 | S241: =IF(B241<>"","Living","") -> Living
A242: ="P"&TEXT(ROW()-1,"000") -> P241 | B242: عبدالعزيز | C242: عبدالله | D242: محمد | E242: عبدالله | F242: P239 | G242: Male | K242: =IF(F242="",1,IFERROR(VLOOKUP(F242,A:K,11,FALSE)+1,1)) -> 6 | L242: =IF(F242="","الأصل",IF(VLOOKUP(F242,A:L,12,FALSE)="الأصل","الفرع "&K242-1,VLOOKUP(F242,A:L,12,FALSE))) -> العبدالكريم | M242: =IF(B242<>"",IF(C242<>"",CONCATENATE(B242," بن ",C242," بن ",D242," ",E242),CONCATENATE(B242," ",E242)),"") -> عبدالعزيز بن عبدالله بن محمد عبدالله | N242: =IF(B242<>"",IF(C242<>"",CONCATENATE(B242," bin ",C242," bin ",D242," Al-",E242),CONCATENATE(B242," Al-",E242)),"") -> عبدالعزيز bin عبدالله bin محمد Al-عبدالله | O242: =IF(H242<>"",YEAR(TODAY())-H242,"") | P242: =I242+J242 -> 0 | S242: =IF(B242<>"","Living","") -> Living
A243: ="P"&TEXT(ROW()-1,"000") -> P242 | B243: عبدالله | C243: محمد | D243: عبدالله | E243: محمد | F243: P240 | G243: Male | K243: =IF(F243="",1,IFERROR(VLOOKUP(F243,A:K,11,FALSE)+1,1)) -> 7 | L243: =IF(F243="","الأصل",IF(VLOOKUP(F243,A:L,12,FALSE)="الأصل","الفرع "&K243-1,VLOOKUP(F243,A:L,12,FALSE))) -> العبدالكريم | M243: =IF(B243<>"",IF(C243<>"",CONCATENATE(B243," بن ",C243," بن ",D243," ",E243),CONCATENATE(B243," ",E243)),"") -> عبدالله بن محمد بن عبدالله محمد | N243: =IF(B243<>"",IF(C243<>"",CONCATENATE(B243," bin ",C243," bin ",D243," Al-",E243),CONCATENATE(B243," Al-",E243)),"") -> عبدالله bin محمد bin عبدالله Al-محمد | O243: =IF(H243<>"",YEAR(TODAY())-H243,"") | P243: =I243+J243 -> 0 | S243: =IF(B243<>"","Living","") -> Living
A244: ="P"&TEXT(ROW()-1,"000") -> P243 | B244: عبدالعزيز | C244: محمد | D244: عبدالله | E244: محمد | F244: P240 | G244: Male | K244: =IF(F244="",1,IFERROR(VLOOKUP(F244,A:K,11,FALSE)+1,1)) -> 7 | L244: =IF(F244="","الأصل",IF(VLOOKUP(F244,A:L,12,FALSE)="الأصل","الفرع "&K244-1,VLOOKUP(F244,A:L,12,FALSE))) -> العبدالكريم | M244: =IF(B244<>"",IF(C244<>"",CONCATENATE(B244," بن ",C244," بن ",D244," ",E244),CONCATENATE(B244," ",E244)),"") -> عبدالعزيز بن محمد بن عبدالله محمد | N244: =IF(B244<>"",IF(C244<>"",CONCATENATE(B244," bin ",C244," bin ",D244," Al-",E244),CONCATENATE(B244," Al-",E244)),"") -> عبدالعزيز bin محمد bin عبدالله Al-محمد | O244: =IF(H244<>"",YEAR(TODAY())-H244,"") | P244: =I244+J244 -> 0 | S244: =IF(B244<>"","Living","") -> Living
A245: ="P"&TEXT(ROW()-1,"000") -> P244 | B245: يوسف | C245: محمد | D245: عبدالله | E245: محمد | F245: P240 | G245: Male | K245: =IF(F245="",1,IFERROR(VLOOKUP(F245,A:K,11,FALSE)+1,1)) -> 7 | L245: =IF(F245="","الأصل",IF(VLOOKUP(F245,A:L,12,FALSE)="الأصل","الفرع "&K245-1,VLOOKUP(F245,A:L,12,FALSE))) -> العبدالكريم | M245: =IF(B245<>"",IF(C245<>"",CONCATENATE(B245," بن ",C245," بن ",D245," ",E245),CONCATENATE(B245," ",E245)),"") -> يوسف بن محمد بن عبدالله محمد | N245: =IF(B245<>"",IF(C245<>"",CONCATENATE(B245," bin ",C245," bin ",D245," Al-",E245),CONCATENATE(B245," Al-",E245)),"") -> يوسف bin محمد bin عبدالله Al-محمد | O245: =IF(H245<>"",YEAR(TODAY())-H245,"") | P245: =I245+J245 -> 0 | S245: =IF(B245<>"","Living","") -> Living
A246: ="P"&TEXT(ROW()-1,"000") -> P245 | B246: ربى | C246: محمد | D246: عبدالله | E246: محمد | F246: P240 | G246: Female | K246: =IF(F246="",1,IFERROR(VLOOKUP(F246,A:K,11,FALSE)+1,1)) -> 7 | L246: =IF(F246="","الأصل",IF(VLOOKUP(F246,A:L,12,FALSE)="الأصل","الفرع "&K246-1,VLOOKUP(F246,A:L,12,FALSE))) -> العبدالكريم | M246: =IF(B246<>"",IF(C246<>"",CONCATENATE(B246," بن ",C246," بن ",D246," ",E246),CONCATENATE(B246," ",E246)),"") -> ربى بن محمد بن عبدالله محمد | N246: =IF(B246<>"",IF(C246<>"",CONCATENATE(B246," bin ",C246," bin ",D246," Al-",E246),CONCATENATE(B246," Al-",E246)),"") -> ربى bin محمد bin عبدالله Al-محمد | O246: =IF(H246<>"",YEAR(TODAY())-H246,"") | P246: =I246+J246 -> 0 | S246: =IF(B246<>"","Living","") -> Living
A247: ="P"&TEXT(ROW()-1,"000") -> P246 | B247: سارة | C247: محمد | D247: عبدالله | E247: محمد | F247: P240 | G247: Female | K247: =IF(F247="",1,IFERROR(VLOOKUP(F247,A:K,11,FALSE)+1,1)) -> 7 | L247: =IF(F247="","الأصل",IF(VLOOKUP(F247,A:L,12,FALSE)="الأصل","الفرع "&K247-1,VLOOKUP(F247,A:L,12,FALSE))) -> العبدالكريم | M247: =IF(B247<>"",IF(C247<>"",CONCATENATE(B247," بن ",C247," بن ",D247," ",E247),CONCATENATE(B247," ",E247)),"") -> سارة بن محمد بن عبدالله محمد | N247: =IF(B247<>"",IF(C247<>"",CONCATENATE(B247," bin ",C247," bin ",D247," Al-",E247),CONCATENATE(B247," Al-",E247)),"") -> سارة bin محمد bin عبدالله Al-محمد | O247: =IF(H247<>"",YEAR(TODAY())-H247,"") | P247: =I247+J247 -> 0 | S247: =IF(B247<>"","Living","") -> Living
... A269: ="P"&TEXT(ROW()-1,"000") -> P268 | B269: هالة | C269: عبدالعزيز | D269: ابراهيم | E269: ناصر | F269: P015 | G269: Female | K269: =IF(F269="",1,IFERROR(VLOOKUP(F269,A:K,11,FALSE)+1,1)) -> 6 | L269: =IF(F269="","الأصل",IF(VLOOKUP(F269,A:L,12,FALSE)="الأصل","الفرع "&K269-1,VLOOKUP(F269,A:L,12,FALSE))) -> الابراهيم | M269: =IF(B269<>"",IF(C269<>"",CONCATENATE(B269," بن ",C269," بن ",D269," ",E269),CONCATENATE(B269," ",E269)),"") -> هالة بن عبدالعزيز بن ابراهيم ناصر | N269: =IF(B269<>"",IF(C269<>"",CONCATENATE(B269," bin ",C269," bin ",D269," Al-",E269),CONCATENATE(B269," Al-",E269)),"") -> هالة bin عبدالعزيز bin ابراهيم Al-ناصر | O269: =IF(H269<>"",YEAR(TODAY())-H269,"") | P269: =I269+J269 -> 0 | S269: =IF(B269<>"","Living","") -> Living
A270: ="P"&TEXT(ROW()-1,"000") -> P269 | B270: عثمان | C270: عبدالكريم | D270: حمد | F270: P003 | G270: Male | K270: =IF(F270="",1,IFERROR(VLOOKUP(F270,A:K,11,FALSE)+1,1)) -> 3 | L270: =IF(F270="","الأصل",IF(VLOOKUP(F270,A:L,12,FALSE)="الأصل","الفرع "&K270-1,VLOOKUP(F270,A:L,12,FALSE))) -> العبدالكريم | M270: =IF(B270<>"",IF(C270<>"",CONCATENATE(B270," بن ",C270," بن ",D270," ",E270),CONCATENATE(B270," ",E270)),"") -> عثمان بن عبدالكريم بن حمد | N270: =IF(B270<>"",IF(C270<>"",CONCATENATE(B270," bin ",C270," bin ",D270," Al-",E270),CONCATENATE(B270," Al-",E270)),"") -> عثمان bin عبدالكريم bin حمد Al- | O270: =IF(H270<>"",YEAR(TODAY())-H270,"") | P270: =I270+J270 -> 0 | S270: =IF(B270<>"","Living","") -> Living
A271: ="P"&TEXT(ROW()-1,"000") -> P270 | B271: عبدالرحمن | C271: عثمان | D271: عبدالكريم | E271: حمد | F271: P269 | G271: Male | K271: =IF(F271="",1,IFERROR(VLOOKUP(F271,A:K,11,FALSE)+1,1)) -> 4 | L271: =IF(F271="","الأصل",IF(VLOOKUP(F271,A:L,12,FALSE)="الأصل","الفرع "&K271-1,VLOOKUP(F271,A:L,12,FALSE))) -> العبدالكريم | M271: =IF(B271<>"",IF(C271<>"",CONCATENATE(B271," بن ",C271," بن ",D271," ",E271),CONCATENATE(B271," ",E271)),"") -> عبدالرحمن بن عثمان بن عبدالكريم حمد | N271: =IF(B271<>"",IF(C271<>"",CONCATENATE(B271," bin ",C271," bin ",D271," Al-",E271),CONCATENATE(B271," Al-",E271)),"") -> عبدالرحمن bin عثمان bin عبدالكريم Al-حمد | O271: =IF(H271<>"",YEAR(TODAY())-H271,"") | P271: =I271+J271 -> 0 | S271: =IF(B271<>"","Living","") -> Living
A272: ="P"&TEXT(ROW()-1,"000") -> P271 | B272: عبدالكريم | C272: عثمان | D272: عبدالكريم | E272: حمد | F272: P269 | G272: Male | K272: =IF(F272="",1,IFERROR(VLOOKUP(F272,A:K,11,FALSE)+1,1)) -> 4 | L272: =IF(F272="","الأصل",IF(VLOOKUP(F272,A:L,12,FALSE)="الأصل","الفرع "&K272-1,VLOOKUP(F272,A:L,12,FALSE))) -> العبدالكريم | M272: =IF(B272<>"",IF(C272<>"",CONCATENATE(B272," بن ",C272," بن ",D272," ",E272),CONCATENATE(B272," ",E272)),"") -> عبدالكريم بن عثمان بن عبدالكريم حمد | N272: =IF(B272<>"",IF(C272<>"",CONCATENATE(B272," bin ",C272," bin ",D272," Al-",E272),CONCATENATE(B272," Al-",E272)),"") -> عبدالكريم bin عثمان bin عبدالكريم Al-حمد | O272: =IF(H272<>"",YEAR(TODAY())-H272,"") | P272: =I272+J272 -> 0 | S272: =IF(B272<>"","Living","") -> Living
A273: ="P"&TEXT(ROW()-1,"000") -> P272 | B273: دخيل | C273: عثمان | D273: عبدالكريم | E273: حمد | F273: P269 | G273: Male | K273: =IF(F273="",1,IFERROR(VLOOKUP(F273,A:K,11,FALSE)+1,1)) -> 4 | L273: =IF(F273="","الأصل",IF(VLOOKUP(F273,A:L,12,FALSE)="الأصل","الفرع "&K273-1,VLOOKUP(F273,A:L,12,FALSE))) -> العبدالكريم | M273: =IF(B273<>"",IF(C273<>"",CONCATENATE(B273," بن ",C273," بن ",D273," ",E273),CONCATENATE(B273," ",E273)),"") -> دخيل بن عثمان بن عبدالكريم حمد | N273: =IF(B273<>"",IF(C273<>"",CONCATENATE(B273," bin ",C273," bin ",D273," Al-",E273),CONCATENATE(B273," Al-",E273)),"") -> دخيل bin عثمان bin عبدالكريم Al-حمد | O273: =IF(H273<>"",YEAR(TODAY())-H273,"") | P273: =I273+J273 -> 0 | S273: =IF(B273<>"","Living","") -> Living
A274: ="P"&TEXT(ROW()-1,"000") -> P273 | B274: عثمان | C274: عبدالكريم | D274: عثمان | E274: عبدالكريم | F274: P271 | G274: Male | K274: =IF(F274="",1,IFERROR(VLOOKUP(F274,A:K,11,FALSE)+1,1)) -> 5 | L274: =IF(F274="","الأصل",IF(VLOOKUP(F274,A:L,12,FALSE)="الأصل","الفرع "&K274-1,VLOOKUP(F274,A:L,12,FALSE))) -> العبدالكريم | M274: =IF(B274<>"",IF(C274<>"",CONCATENATE(B274," بن ",C274," بن ",D274," ",E274),CONCATENATE(B274," ",E274)),"") -> عثمان بن عبدالكريم بن عثمان عبدالكريم | N274: =IF(B274<>"",IF(C274<>"",CONCATENATE(B274," bin ",C274," bin ",D274," Al-",E274),CONCATENATE(B274," Al-",E274)),"") -> عثمان bin عبدالكريم bin عثمان Al-عبدالكريم | O274: =IF(H274<>"",YEAR(TODAY())-H274,"") | P274: =I274+J274 -> 0 | S274: =IF(B274<>"","Living","") -> Living
A275: ="P"&TEXT(ROW()-1,"000") -> P274 | B275: عبدالرحمن | C275: عبدالكريم | D275: عثمان | E275: عبدالكريم | F275: P271 | G275: Male | K275: =IF(F275="",1,IFERROR(VLOOKUP(F275,A:K,11,FALSE)+1,1)) -> 5 | L275: =IF(F275="","الأصل",IF(VLOOKUP(F275,A:L,12,FALSE)="الأصل","الفرع "&K275-1,VLOOKUP(F275,A:L,12,FALSE))) -> العبدالكريم | M275: =IF(B275<>"",IF(C275<>"",CONCATENATE(B275," بن ",C275," بن ",D275," ",E275),CONCATENATE(B275," ",E275)),"") -> عبدالرحمن بن عبدالكريم بن عثمان عبدالكريم | N275: =IF(B275<>"",IF(C275<>"",CONCATENATE(B275," bin ",C275," bin ",D275," Al-",E275),CONCATENATE(B275," Al-",E275)),"") -> عبدالرحمن bin عبدالكريم bin عثمان Al-عبدالكريم | O275: =IF(H275<>"",YEAR(TODAY())-H275,"") | P275: =I275+J275 -> 0 | S275: =IF(B275<>"","Living","") -> Living
...

Sheet TREE
A1: 🌳 شجرة العائلة التفاعلية - INTERACTIVE FAMILY TREE
B3: GEN 1 | F3: GEN 2 | J3: GEN 3 | N3: GEN 4 | R3: GEN 5 | V3: GEN 6
B5: {=IF(COUNTIF(REGISTRY!K:K,1)>0,INDEX(REGISTRY!M:M,MATCH(1,REGISTRY!K:K,0)),"No Root")} -> حمد ال شايع
F8: {=IFERROR(INDEX(REGISTRY!M:M,SMALL(IF(REGISTRY!K:K=2,ROW(REGISTRY!K:K)),1)),"")} -> ابراهيم بن حمد بن -
F12: {=IFERROR(INDEX(REGISTRY!M:M,SMALL(IF(REGISTRY!K:K=2,ROW(REGISTRY!K:K)),2)),"")} -> عبدالكريم بن حمد بن -
F16: {=IFERROR(INDEX(REGISTRY!M:M,SMALL(IF(REGISTRY!K:K=2,ROW(REGISTRY!K:K)),3)),"")} -> فوزان بن حمد بن -
F20: {=IFERROR(INDEX(REGISTRY!M:M,SMALL(IF(REGISTRY!K:K=2,ROW(REGISTRY!K:K)),4)),"")}
F24: {=IFERROR(INDEX(REGISTRY!M:M,SMALL(IF(REGISTRY!K:K=2,ROW(REGISTRY!K:K)),5)),"")}

Sheet FATHER_LIST
A1: ID | B1: Full Name | C1: Generation | D1: Children | E1: Branch
A2: =IF(REGISTRY!G2="Male",REGISTRY!A2,"") | B2: =IF(REGISTRY!G2="Male",REGISTRY!M2,"") | C2: =IF(REGISTRY!G2="Male",REGISTRY!K2,"") | D2: =IF(REGISTRY!G2="Male",REGISTRY!P2,"") | E2: =IF(REGISTRY!G2="Male",REGISTRY!L2,"")
A3: =IF(REGISTRY!G3="Male",REGISTRY!A3,"") -> P002 | B3: =IF(REGISTRY!G3="Male",REGISTRY!M3,"") -> ابراهيم بن حمد بن - | C3: =IF(REGISTRY!G3="Male",REGISTRY!K3,"") -> 2 | D3: =IF(REGISTRY!G3="Male",REGISTRY!P3,"") -> 0 | E3: =IF(REGISTRY!G3="Male",REGISTRY!L3,"") -> الابراهيم
A4: =IF(REGISTRY!G4="Male",REGISTRY!A4,"") -> P003 | B4: =IF(REGISTRY!G4="Male",REGISTRY!M4,"") -> عبدالكريم بن حمد بن - | C4: =IF(REGISTRY!G4="Male",REGISTRY!K4,"") -> 2 | D4: =IF(REGISTRY!G4="Male",REGISTRY!P4,"") -> 0 | E4: =IF(REGISTRY!G4="Male",REGISTRY!L4,"") -> العبدالكريم
A5: =IF(REGISTRY!G5="Male",REGISTRY!A5,"") -> P004 | B5: =IF(REGISTRY!G5="Male",REGISTRY!M5,"") -> فوزان بن حمد بن - | C5: =IF(REGISTRY!G5="Male",REGISTRY!K5,"") -> 2 | D5: =IF(REGISTRY!G5="Male",REGISTRY!P5,"") -> 0 | E5: =IF(REGISTRY!G5="Male",REGISTRY!L5,"") -> الفوزان
A6: =IF(REGISTRY!G6="Male",REGISTRY!A6,"") -> P005 | B6: =IF(REGISTRY!G6="Male",REGISTRY!M6,"") -> محمد بن ابراهيم بن حمد | C6: =IF(REGISTRY!G6="Male",REGISTRY!K6,"") -> 3 | D6: =IF(REGISTRY!G6="Male",REGISTRY!P6,"") -> 0 | E6: =IF(REGISTRY!G6="Male",REGISTRY!L6,"") -> الابراهيم
A7: =IF(REGISTRY!G7="Male",REGISTRY!A7,"") -> P006 | B7: =IF(REGISTRY!G7="Male",REGISTRY!M7,"") -> ناصر بن ابراهيم بن حمد | C7: =IF(REGISTRY!G7="Male",REGISTRY!K7,"") -> 3 | D7: =IF(REGISTRY!G7="Male",REGISTRY!P7,"") -> 0 | E7: =IF(REGISTRY!G7="Male",REGISTRY!L7,"") -> الابراهيم
A8: =IF(REGISTRY!G8="Male",REGISTRY!A8,"") -> P007 | B8: =IF(REGISTRY!G8="Male",REGISTRY!M8,"") -> ابراهيم بن محمد بن ابراهيم حمد | C8: =IF(REGISTRY!G8="Male",REGISTRY!K8,"") -> 4 | D8: =IF(REGISTRY!G8="Male",REGISTRY!P8,"") -> 0 | E8: =IF(REGISTRY!G8="Male",REGISTRY!L8,"") -> الابراهيم
A9: =IF(REGISTRY!G9="Male",REGISTRY!A9,"") -> P008 | B9: =IF(REGISTRY!G9="Male",REGISTRY!M9,"") -> عبدالمحسن بن محمد بن ابراهيم حمد | C9: =IF(REGISTRY!G9="Male",REGISTRY!K9,"") -> 4 | D9: =IF(REGISTRY!G9="Male",REGISTRY!P9,"") -> 0 | E9: =IF(REGISTRY!G9="Male",REGISTRY!L9,"") -> الابراهيم
A10: =IF(REGISTRY!G10="Male",REGISTRY!A10,"") -> P009 | B10: =IF(REGISTRY!G10="Male",REGISTRY!M10,"") -> عبدالرحمن بن محمد بن ابراهيم حمد | C10: =IF(REGISTRY!G10="Male",REGISTRY!K10,"") -> 4 | D10: =IF(REGISTRY!G10="Male",REGISTRY!P10,"") -> 0 | E10: =IF(REGISTRY!G10="Male",REGISTRY!L10,"") -> الابراهيم
A11: =IF(REGISTRY!G11="Male",REGISTRY!A11,"") -> P010 | B11: =IF(REGISTRY!G11="Male",REGISTRY!M11,"") -> عبدالمحسن بن ناصر بن ابراهيم حمد | C11: =IF(REGISTRY!G11="Male",REGISTRY!K11,"") -> 4 | D11: =IF(REGISTRY!G11="Male",REGISTRY!P11,"") -> 0 | E11: =IF(REGISTRY!G11="Male",REGISTRY!L11,"") -> الابراهيم
A12: =IF(REGISTRY!G12="Male",REGISTRY!A12,"") -> P011 | B12: =IF(REGISTRY!G12="Male",REGISTRY!M12,"") -> ابراهيم بن ناصر بن ابراهيم حمد | C12: =IF(REGISTRY!G12="Male",REGISTRY!K12,"") -> 4 | D12: =IF(REGISTRY!G12="Male",REGISTRY!P12,"") -> 0 | E12: =IF(REGISTRY!G12="Male",REGISTRY!L12,"") -> الابراهيم
A13: =IF(REGISTRY!G13="Male",REGISTRY!A13,"") -> P012 | B13: =IF(REGISTRY!G13="Male",REGISTRY!M13,"") -> ناصر بن ابراهيم بن ناصر ابراهيم | C13: =IF(REGISTRY!G13="Male",REGISTRY!K13,"") -> 5 | D13: =IF(REGISTRY!G13="Male",REGISTRY!P13,"") -> 0 | E13: =IF(REGISTRY!G13="Male",REGISTRY!L13,"") -> الابراهيم
... A67: =IF(REGISTRY!G67="Male",REGISTRY!A67,"") | B67: =IF(REGISTRY!G67="Male",REGISTRY!M67,"") | C67: =IF(REGISTRY!G67="Male",REGISTRY!K67,"") | D67: =IF(REGISTRY!G67="Male",REGISTRY!P67,"") | E67: =IF(REGISTRY!G67="Male",REGISTRY!L67,"")
A68: =IF(#REF!="Male",#REF!,"") -> #REF! | B68: =IF(#REF!="Male",#REF!,"") -> #REF! | C68: =IF(#REF!="Male",#REF!,"") -> #REF! | D68: =IF(#REF!="Male",#REF!,"") -> #REF! | E68: =IF(#REF!="Male",#REF!,"") -> #REF!
A69: =IF(#REF!="Male",#REF!,"") -> #REF! | B69: =IF(#REF!="Male",#REF!,"") -> #REF! | C69: =IF(#REF!="Male",#REF!,"") -> #REF! | D69: =IF(#REF!="Male",#REF!,"") -> #REF! | E69: =IF(#REF!="Male",#REF!,"") -> #REF!
A70: =IF(REGISTRY!G68="Male",REGISTRY!A68,"") | B70: =IF(REGISTRY!G68="Male",REGISTRY!M68,"") | C70: =IF(REGISTRY!G68="Male",REGISTRY!K68,"") | D70: =IF(REGISTRY!G68="Male",REGISTRY!P68,"") | E70: =IF(REGISTRY!G68="Male",REGISTRY!L68,"")
A71: =IF(REGISTRY!G69="Male",REGISTRY!A69,"") | B71: =IF(REGISTRY!G69="Male",REGISTRY!M69,"") | C71: =IF(REGISTRY!G69="Male",REGISTRY!K69,"") | D71: =IF(REGISTRY!G69="Male",REGISTRY!P69,"") | E71: =IF(REGISTRY!G69="Male",REGISTRY!L69,"")
A72: =IF(REGISTRY!G70="Male",REGISTRY!A70,"") | B72: =IF(REGISTRY!G70="Male",REGISTRY!M70,"") | C72: =IF(REGISTRY!G70="Male",REGISTRY!K70,"") | D72: =IF(REGISTRY!G70="Male",REGISTRY!P70,"") | E72: =IF(REGISTRY!G70="Male",REGISTRY!L70,"")
A73: =IF(REGISTRY!G71="Male",REGISTRY!A71,"") | B73: =IF(REGISTRY!G71="Male",REGISTRY!M71,"") | C73: =IF(REGISTRY!G71="Male",REGISTRY!K71,"") | D73: =IF(REGISTRY!G71="Male",REGISTRY!P71,"") | E73: =IF(REGISTRY!G71="Male",REGISTRY!L71,"")
A74: =IF(REGISTRY!G72="Male",REGISTRY!A72,"") | B74: =IF(REGISTRY!G72="Male",REGISTRY!M72,"") | C74: =IF(REGISTRY!G72="Male",REGISTRY!K72,"") | D74: =IF(REGISTRY!G72="Male",REGISTRY!P72,"") | E74: =IF(REGISTRY!G72="Male",REGISTRY!L72,"")
A75: =IF(#REF!="Male",#REF!,"") -> #REF! | B75: =IF(#REF!="Male",#REF!,"") -> #REF! | C75: =IF(#REF!="Male",#REF!,"") -> #REF! | D75: =IF(#REF!="Male",#REF!,"") -> #REF! | E75: =IF(#REF!="Male",#REF!,"") -> #REF!
A76: =IF(#REF!="Male",#REF!,"") -> #REF! | B76: =IF(#REF!="Male",#REF!,"") -> #REF! | C76: =IF(#REF!="Male",#REF!,"") -> #REF! | D76: =IF(#REF!="Male",#REF!,"") -> #REF! | E76: =IF(#REF!="Male",#REF!,"") -> #REF!
A77: =IF(REGISTRY!G73="Male",REGISTRY!A73,"") | B77: =IF(REGISTRY!G73="Male",REGISTRY!M73,"") | C77: =IF(REGISTRY!G73="Male",REGISTRY!K73,"") | D77: =IF(REGISTRY!G73="Male",REGISTRY!P73,"") | E77: =IF(REGISTRY!G73="Male",REGISTRY!L73,"")
A78: =IF(#REF!="Male",#REF!,"") -> #REF! | B78: =IF(#REF!="Male",#REF!,"") -> #REF! | C78: =IF(#REF!="Male",#REF!,"") -> #REF! | D78: =IF(#REF!="Male",#REF!,"") -> #REF! | E78: =IF(#REF!="Male",#REF!,"") -> #REF!
A79: =IF(#REF!="Male",#REF!,"") -> #REF! | B79: =IF(#REF!="Male",#REF!,"") -> #REF! | C79: =IF(#REF!="Male",#REF!,"") -> #REF! | D79: =IF(#REF!="Male",#REF!,"") -> #REF! | E79: =IF(#REF!="Male",#REF!,"") -> #REF!
A80: =IF(#REF!="Male",#REF!,"") -> #REF! | B80: =IF(#REF!="Male",#REF!,"") -> #REF! | C80: =IF(#REF!="Male",#REF!,"") -> #REF! | D80: =IF(#REF!="Male",#REF!,"") -> #REF! | E80: =IF(#REF!="Male",#REF!,"") -> #REF!
A81: =IF(#REF!="Male",#REF!,"") -> #REF! | B81: =IF(#REF!="Male",#REF!,"") -> #REF! | C81: =IF(#REF!="Male",#REF!,"") -> #REF! | D81: =IF(#REF!="Male",#REF!,"") -> #REF! | E81: =IF(#REF!="Male",#REF!,"") -> #REF!
A82: =IF(REGISTRY!G74="Male",REGISTRY!A74,"") | B82: =IF(REGISTRY!G74="Male",REGISTRY!M74,"") | C82: =IF(REGISTRY!G74="Male",REGISTRY!K74,"") | D82: =IF(REGISTRY!G74="Male",REGISTRY!P74,"") | E82: =IF(REGISTRY!G74="Male",REGISTRY!L74,"")
A83: =IF(REGISTRY!G75="Male",REGISTRY!A75,"") | B83: =IF(REGISTRY!G75="Male",REGISTRY!M75,"") | C83: =IF(REGISTRY!G75="Male",REGISTRY!K75,"") | D83: =IF(REGISTRY!G75="Male",REGISTRY!P75,"") | E83: =IF(REGISTRY!G75="Male",REGISTRY!L75,"")
A84: =IF(REGISTRY!G76="Male",REGISTRY!A76,"") | B84: =IF(REGISTRY!G76="Male",REGISTRY!M76,"") | C84: =IF(REGISTRY!G76="Male",REGISTRY!K76,"") | D84: =IF(REGISTRY!G76="Male",REGISTRY!P76,"") | E84: =IF(REGISTRY!G76="Male",REGISTRY!L76,"")
A85: =IF(REGISTRY!G77="Male",REGISTRY!A77,"") | B85: =IF(REGISTRY!G77="Male",REGISTRY!M77,"") | C85: =IF(REGISTRY!G77="Male",REGISTRY!K77,"") | D85: =IF(REGISTRY!G77="Male",REGISTRY!P77,"") | E85: =IF(REGISTRY!G77="Male",REGISTRY!L77,"")
A86: =IF(REGISTRY!G78="Male",REGISTRY!A78,"") | B86: =IF(REGISTRY!G78="Male",REGISTRY!M78,"") | C86: =IF(REGISTRY!G78="Male",REGISTRY!K78,"") | D86: =IF(REGISTRY!G78="Male",REGISTRY!P78,"") | E86: =IF(REGISTRY!G78="Male",REGISTRY!L78,"")
A87: =IF(REGISTRY!G79="Male",REGISTRY!A79,"") | B87: =IF(REGISTRY!G79="Male",REGISTRY!M79,"") | C87: =IF(REGISTRY!G79="Male",REGISTRY!K79,"") | D87: =IF(REGISTRY!G79="Male",REGISTRY!P79,"") | E87: =IF(REGISTRY!G79="Male",REGISTRY!L79,"")
A88: =IF(#REF!="Male",#REF!,"") -> #REF! | B88: =IF(#REF!="Male",#REF!,"") -> #REF! | C88: =IF(#REF!="Male",#REF!,"") -> #REF! | D88: =IF(#REF!="Male",#REF!,"") -> #REF! | E88: =IF(#REF!="Male",#REF!,"") -> #REF!
A89: =IF(REGISTRY!G80="Male",REGISTRY!A80,"") | B89: =IF(REGISTRY!G80="Male",REGISTRY!M80,"") | C89: =IF(REGISTRY!G80="Male",REGISTRY!K80,"") | D89: =IF(REGISTRY!G80="Male",REGISTRY!P80,"") | E89: =IF(REGISTRY!G80="Male",REGISTRY!L80,"")
A90: =IF(REGISTRY!G81="Male",REGISTRY!A81,"") | B90: =IF(REGISTRY!G81="Male",REGISTRY!M81,"") | C90: =IF(REGISTRY!G81="Male",REGISTRY!K81,"") | D90: =IF(REGISTRY!G81="Male",REGISTRY!P81,"") | E90: =IF(REGISTRY!G81="Male",REGISTRY!L81,"")
A91: =IF(REGISTRY!G82="Male",REGISTRY!A82,"") | B91: =IF(REGISTRY!G82="Male",REGISTRY!M82,"") | C91: =IF(REGISTRY!G82="Male",REGISTRY!K82,"") | D91: =IF(REGISTRY!G82="Male",REGISTRY!P82,"") | E91: =IF(REGISTRY!G82="Male",REGISTRY!L82,"")
A92: =IF(#REF!="Male",#REF!,"") -> #REF! | B92: =IF(#REF!="Male",#REF!,"") -> #REF! | C92: =IF(#REF!="Male",#REF!,"") -> #REF! | D92: =IF(#REF!="Male",#REF!,"") -> #REF! | E92: =IF(#REF!="Male",#REF!,"") -> #REF!
A93: =IF(#REF!="Male",#REF!,"") -> #REF! | B93: =IF(#REF!="Male",#REF!,"") -> #REF! | C93: =IF(#REF!="Male",#REF!,"") -> #REF! | D93: =IF(#REF!="Male",#REF!,"") -> #REF! | E93: =IF(#REF!="Male",#REF!,"") -> #REF!
...
